try {
    console.log(a + b)
} catch(err){
    console.log(err)
    console.log("There Was an Error")
    console.log("The Error was saved in the error log")
}

console.log("My Program does not stop")